[2024-06-27T06:52:24.494+0000] {taskinstance.py:1979} INFO - Dependencies all met for dep_context=non-requeueable deps ti=<TaskInstance: dag_sentiment_analysis.extract_load scheduled__2024-06-26T00:00:00+00:00 [queued]>
[2024-06-27T06:52:24.503+0000] {taskinstance.py:1979} INFO - Dependencies all met for dep_context=requeueable deps ti=<TaskInstance: dag_sentiment_analysis.extract_load scheduled__2024-06-26T00:00:00+00:00 [queued]>
[2024-06-27T06:52:24.504+0000] {taskinstance.py:2193} INFO - Starting attempt 2 of 2
[2024-06-27T06:52:24.523+0000] {taskinstance.py:2217} INFO - Executing <Task(PythonOperator): extract_load> on 2024-06-26 00:00:00+00:00
[2024-06-27T06:52:24.529+0000] {standard_task_runner.py:60} INFO - Started process 456 to run task
[2024-06-27T06:52:24.532+0000] {standard_task_runner.py:87} INFO - Running: ['***', 'tasks', 'run', 'dag_sentiment_analysis', 'extract_load', 'scheduled__2024-06-26T00:00:00+00:00', '--job-id', '30', '--raw', '--subdir', 'DAGS_FOLDER/dag_sentiment_analysis.py', '--cfg-path', '/tmp/tmpnkh1on6t']
[2024-06-27T06:52:24.535+0000] {standard_task_runner.py:88} INFO - Job 30: Subtask extract_load
[2024-06-27T06:52:24.552+0000] {logging_mixin.py:188} WARNING - /home/***/.local/lib/python3.10/site-packages/***/settings.py:194 DeprecationWarning: The sql_alchemy_conn option in [core] has been moved to the sql_alchemy_conn option in [database] - the old setting has been used, but please update your config.
[2024-06-27T06:52:24.590+0000] {task_command.py:423} INFO - Running <TaskInstance: dag_sentiment_analysis.extract_load scheduled__2024-06-26T00:00:00+00:00 [running]> on host 751e0ee69c38
[2024-06-27T06:52:24.666+0000] {taskinstance.py:2513} INFO - Exporting env vars: AIRFLOW_CTX_DAG_OWNER='de-team' AIRFLOW_CTX_DAG_ID='dag_sentiment_analysis' AIRFLOW_CTX_TASK_ID='extract_load' AIRFLOW_CTX_EXECUTION_DATE='2024-06-26T00:00:00+00:00' AIRFLOW_CTX_TRY_NUMBER='2' AIRFLOW_CTX_DAG_RUN_ID='scheduled__2024-06-26T00:00:00+00:00'
[2024-06-27T06:52:57.103+0000] {logging_mixin.py:188} INFO - SSL handshake failed: ac-xsr1qg7-shard-00-00.0h2vioi.mongodb.net:27017: [SSL: TLSV1_ALERT_INTERNAL_ERROR] tlsv1 alert internal error (_ssl.c:1007) (configured timeouts: socketTimeoutMS: 20000.0ms, connectTimeoutMS: 20000.0ms),SSL handshake failed: ac-xsr1qg7-shard-00-01.0h2vioi.mongodb.net:27017: [SSL: TLSV1_ALERT_INTERNAL_ERROR] tlsv1 alert internal error (_ssl.c:1007) (configured timeouts: socketTimeoutMS: 20000.0ms, connectTimeoutMS: 20000.0ms),SSL handshake failed: ac-xsr1qg7-shard-00-02.0h2vioi.mongodb.net:27017: [SSL: TLSV1_ALERT_INTERNAL_ERROR] tlsv1 alert internal error (_ssl.c:1007) (configured timeouts: socketTimeoutMS: 20000.0ms, connectTimeoutMS: 20000.0ms), Timeout: 30s, Topology Description: <TopologyDescription id: 667d0c2a902e0742eae164b2, topology_type: ReplicaSetNoPrimary, servers: [<ServerDescription ('ac-xsr1qg7-shard-00-00.0h2vioi.mongodb.net', 27017) server_type: Unknown, rtt: None, error=AutoReconnect('SSL handshake failed: ac-xsr1qg7-shard-00-00.0h2vioi.mongodb.net:27017: [SSL: TLSV1_ALERT_INTERNAL_ERROR] tlsv1 alert internal error (_ssl.c:1007) (configured timeouts: socketTimeoutMS: 20000.0ms, connectTimeoutMS: 20000.0ms)')>, <ServerDescription ('ac-xsr1qg7-shard-00-01.0h2vioi.mongodb.net', 27017) server_type: Unknown, rtt: None, error=AutoReconnect('SSL handshake failed: ac-xsr1qg7-shard-00-01.0h2vioi.mongodb.net:27017: [SSL: TLSV1_ALERT_INTERNAL_ERROR] tlsv1 alert internal error (_ssl.c:1007) (configured timeouts: socketTimeoutMS: 20000.0ms, connectTimeoutMS: 20000.0ms)')>, <ServerDescription ('ac-xsr1qg7-shard-00-02.0h2vioi.mongodb.net', 27017) server_type: Unknown, rtt: None, error=AutoReconnect('SSL handshake failed: ac-xsr1qg7-shard-00-02.0h2vioi.mongodb.net:27017: [SSL: TLSV1_ALERT_INTERNAL_ERROR] tlsv1 alert internal error (_ssl.c:1007) (configured timeouts: socketTimeoutMS: 20000.0ms, connectTimeoutMS: 20000.0ms)')>]>
[2024-06-27T06:52:57.105+0000] {taskinstance.py:2731} ERROR - Task failed with exception
Traceback (most recent call last):
  File "/home/airflow/.local/lib/python3.10/site-packages/airflow/models/taskinstance.py", line 444, in _execute_task
    result = _execute_callable(context=context, **execute_callable_kwargs)
  File "/home/airflow/.local/lib/python3.10/site-packages/airflow/models/taskinstance.py", line 414, in _execute_callable
    return execute_callable(context=context, **execute_callable_kwargs)
  File "/home/airflow/.local/lib/python3.10/site-packages/airflow/operators/python.py", line 200, in execute
    return_value = self.execute_callable()
  File "/home/airflow/.local/lib/python3.10/site-packages/airflow/operators/python.py", line 217, in execute_callable
    return self.python_callable(*self.op_args, **self.op_kwargs)
  File "/opt/airflow/plugins/finnhub_mongodb_loader.py", line 7, in extract_load
    collection = mongodb_loader.load('news', 'finnhub_news')
  File "/opt/airflow/plugins/mongodb_loader.py", line 27, in load
    db = mongo_client[database]
TypeError: 'NoneType' object is not subscriptable
[2024-06-27T06:52:57.121+0000] {taskinstance.py:1149} INFO - Marking task as FAILED. dag_id=dag_sentiment_analysis, task_id=extract_load, execution_date=20240626T000000, start_date=20240627T065224, end_date=20240627T065257
[2024-06-27T06:52:57.141+0000] {standard_task_runner.py:107} ERROR - Failed to execute job 30 for task extract_load ('NoneType' object is not subscriptable; 456)
[2024-06-27T06:52:57.197+0000] {local_task_job_runner.py:234} INFO - Task exited with return code 1
[2024-06-27T06:52:57.232+0000] {taskinstance.py:3312} INFO - 0 downstream tasks scheduled from follow-on schedule check
