[2024-06-27T06:47:23.050+0000] {taskinstance.py:1979} INFO - Dependencies all met for dep_context=non-requeueable deps ti=<TaskInstance: dag_sentiment_analysis.extract_load scheduled__2024-06-26T00:00:00+00:00 [queued]>
[2024-06-27T06:47:23.063+0000] {taskinstance.py:1979} INFO - Dependencies all met for dep_context=requeueable deps ti=<TaskInstance: dag_sentiment_analysis.extract_load scheduled__2024-06-26T00:00:00+00:00 [queued]>
[2024-06-27T06:47:23.064+0000] {taskinstance.py:2193} INFO - Starting attempt 1 of 2
[2024-06-27T06:47:23.082+0000] {taskinstance.py:2217} INFO - Executing <Task(PythonOperator): extract_load> on 2024-06-26 00:00:00+00:00
[2024-06-27T06:47:23.090+0000] {standard_task_runner.py:60} INFO - Started process 409 to run task
[2024-06-27T06:47:23.094+0000] {standard_task_runner.py:87} INFO - Running: ['***', 'tasks', 'run', 'dag_sentiment_analysis', 'extract_load', 'scheduled__2024-06-26T00:00:00+00:00', '--job-id', '29', '--raw', '--subdir', 'DAGS_FOLDER/dag_sentiment_analysis.py', '--cfg-path', '/tmp/tmpaoo9u40d']
[2024-06-27T06:47:23.097+0000] {standard_task_runner.py:88} INFO - Job 29: Subtask extract_load
[2024-06-27T06:47:23.115+0000] {logging_mixin.py:188} WARNING - /home/***/.local/lib/python3.10/site-packages/***/settings.py:194 DeprecationWarning: The sql_alchemy_conn option in [core] has been moved to the sql_alchemy_conn option in [database] - the old setting has been used, but please update your config.
[2024-06-27T06:47:23.151+0000] {task_command.py:423} INFO - Running <TaskInstance: dag_sentiment_analysis.extract_load scheduled__2024-06-26T00:00:00+00:00 [running]> on host 751e0ee69c38
[2024-06-27T06:47:24.108+0000] {taskinstance.py:2513} INFO - Exporting env vars: AIRFLOW_CTX_DAG_OWNER='de-team' AIRFLOW_CTX_DAG_ID='dag_sentiment_analysis' AIRFLOW_CTX_TASK_ID='extract_load' AIRFLOW_CTX_EXECUTION_DATE='2024-06-26T00:00:00+00:00' AIRFLOW_CTX_TRY_NUMBER='1' AIRFLOW_CTX_DAG_RUN_ID='scheduled__2024-06-26T00:00:00+00:00'
[2024-06-27T06:47:24.130+0000] {taskinstance.py:2731} ERROR - Task failed with exception
Traceback (most recent call last):
  File "/home/airflow/.local/lib/python3.10/site-packages/urllib3/connection.py", line 203, in _new_conn
    sock = connection.create_connection(
  File "/home/airflow/.local/lib/python3.10/site-packages/urllib3/util/connection.py", line 60, in create_connection
    for res in socket.getaddrinfo(host, port, family, socket.SOCK_STREAM):
  File "/usr/local/lib/python3.10/socket.py", line 955, in getaddrinfo
    for res in _socket.getaddrinfo(host, port, family, type, proto, flags):
socket.gaierror: [Errno -2] Name or service not known

The above exception was the direct cause of the following exception:

Traceback (most recent call last):
  File "/home/airflow/.local/lib/python3.10/site-packages/urllib3/connectionpool.py", line 791, in urlopen
    response = self._make_request(
  File "/home/airflow/.local/lib/python3.10/site-packages/urllib3/connectionpool.py", line 492, in _make_request
    raise new_e
  File "/home/airflow/.local/lib/python3.10/site-packages/urllib3/connectionpool.py", line 468, in _make_request
    self._validate_conn(conn)
  File "/home/airflow/.local/lib/python3.10/site-packages/urllib3/connectionpool.py", line 1097, in _validate_conn
    conn.connect()
  File "/home/airflow/.local/lib/python3.10/site-packages/urllib3/connection.py", line 611, in connect
    self.sock = sock = self._new_conn()
  File "/home/airflow/.local/lib/python3.10/site-packages/urllib3/connection.py", line 210, in _new_conn
    raise NameResolutionError(self.host, self, e) from e
urllib3.exceptions.NameResolutionError: <urllib3.connection.HTTPSConnection object at 0x7f156b381660>: Failed to resolve 'api.finnhub.io' ([Errno -2] Name or service not known)

The above exception was the direct cause of the following exception:

Traceback (most recent call last):
  File "/home/airflow/.local/lib/python3.10/site-packages/requests/adapters.py", line 486, in send
    resp = conn.urlopen(
  File "/home/airflow/.local/lib/python3.10/site-packages/urllib3/connectionpool.py", line 845, in urlopen
    retries = retries.increment(
  File "/home/airflow/.local/lib/python3.10/site-packages/urllib3/util/retry.py", line 515, in increment
    raise MaxRetryError(_pool, url, reason) from reason  # type: ignore[arg-type]
urllib3.exceptions.MaxRetryError: HTTPSConnectionPool(host='api.finnhub.io', port=443): Max retries exceeded with url: /api/v1//news?token=cptts59r01qnga5inj30cptts59r01qnga5inj3g&category=general&minId=0 (Caused by NameResolutionError("<urllib3.connection.HTTPSConnection object at 0x7f156b381660>: Failed to resolve 'api.finnhub.io' ([Errno -2] Name or service not known)"))

During handling of the above exception, another exception occurred:

Traceback (most recent call last):
  File "/home/airflow/.local/lib/python3.10/site-packages/airflow/models/taskinstance.py", line 444, in _execute_task
    result = _execute_callable(context=context, **execute_callable_kwargs)
  File "/home/airflow/.local/lib/python3.10/site-packages/airflow/models/taskinstance.py", line 414, in _execute_callable
    return execute_callable(context=context, **execute_callable_kwargs)
  File "/home/airflow/.local/lib/python3.10/site-packages/airflow/operators/python.py", line 200, in execute
    return_value = self.execute_callable()
  File "/home/airflow/.local/lib/python3.10/site-packages/airflow/operators/python.py", line 217, in execute_callable
    return self.python_callable(*self.op_args, **self.op_kwargs)
  File "/opt/airflow/plugins/finnhub_mongodb_loader.py", line 5, in extract_load
    news = finnhub_loader.scrape_news()
  File "/opt/airflow/plugins/finnhub_loader.py", line 6, in scrape_news
    news = finnhub_client.general_news('general', min_id=0)
  File "/home/airflow/.local/lib/python3.10/site-packages/finnhub/client.py", line 311, in general_news
    return self._get("/news", params={
  File "/home/airflow/.local/lib/python3.10/site-packages/finnhub/client.py", line 71, in _get
    return self._request("get", path, **kwargs)
  File "/home/airflow/.local/lib/python3.10/site-packages/finnhub/client.py", line 40, in _request
    response = getattr(self._session, method)(uri, **kwargs)
  File "/home/airflow/.local/lib/python3.10/site-packages/requests/sessions.py", line 602, in get
    return self.request("GET", url, **kwargs)
  File "/home/airflow/.local/lib/python3.10/site-packages/requests/sessions.py", line 589, in request
    resp = self.send(prep, **send_kwargs)
  File "/home/airflow/.local/lib/python3.10/site-packages/requests/sessions.py", line 703, in send
    r = adapter.send(request, **kwargs)
  File "/home/airflow/.local/lib/python3.10/site-packages/requests/adapters.py", line 519, in send
    raise ConnectionError(e, request=request)
requests.exceptions.ConnectionError: HTTPSConnectionPool(host='api.finnhub.io', port=443): Max retries exceeded with url: /api/v1//news?token=cptts59r01qnga5inj30cptts59r01qnga5inj3g&category=general&minId=0 (Caused by NameResolutionError("<urllib3.connection.HTTPSConnection object at 0x7f156b381660>: Failed to resolve 'api.finnhub.io' ([Errno -2] Name or service not known)"))
[2024-06-27T06:47:24.170+0000] {taskinstance.py:1149} INFO - Marking task as UP_FOR_RETRY. dag_id=dag_sentiment_analysis, task_id=extract_load, execution_date=20240626T000000, start_date=20240627T064723, end_date=20240627T064724
[2024-06-27T06:47:24.202+0000] {standard_task_runner.py:107} ERROR - Failed to execute job 29 for task extract_load (HTTPSConnectionPool(host='api.finnhub.io', port=443): Max retries exceeded with url: /api/v1//news?token=cptts59r01qnga5inj30cptts59r01qnga5inj3g&category=general&minId=0 (Caused by NameResolutionError("<urllib3.connection.HTTPSConnection object at 0x7f156b381660>: Failed to resolve 'api.finnhub.io' ([Errno -2] Name or service not known)")); 409)
[2024-06-27T06:47:24.274+0000] {local_task_job_runner.py:234} INFO - Task exited with return code 1
[2024-06-27T06:47:24.316+0000] {taskinstance.py:3312} INFO - 0 downstream tasks scheduled from follow-on schedule check
